Workbook

Sheet Hensoldt AG
B2: Hensoldt AG Equity Research Report
B5: Table of Contents:
B7: 1. Inputs | H7: Implied Share Price 1 | J7: ='DCF Valuation '!E44 -> 61.208704 | K7: €/share | L7: (Using Terminal Value)
B9: 2. Income Statement | H9: Implied Share Price 2 | J9: ='DCF Valuation '!K44 -> 48.726513 | K9: €/share | L9: (Using Exit Multiple)
B11: 3. Balance Sheet
H12: Current Price | J12: 85.4 | K12: €/share
B13: 4. Cash Flow Statement
H14: Upside Potential 1: | J14: =(J7-J12)/J7 -> -0.39522641
B15: Forecast Sheets:
H16: Upside Potential 2: | J16: =(J9-J12)/J9 -> -0.75263926
B17: 5. Revenue/Expense Forecast
B19: 6. Fixed Asset Forecast
H20: Colour Code
B21: 7. Working Capital / Other Assets | H21: Green: Links to another sheet
H22: Purple: Links to same sheet
B23: 8. Debt & Cash Forecast | H23: Black: Calculations
H24: Red: Discretionary Inputs
B25: Output: | H25: Blue: hard-coded Inputs
B27: 9. DCF Modelling
B29: 10. Competitors KPI's

Sheet Inputs
B1: =_xlfn.CONCAT(C7, " - ", "Inputs -", " In", " ", C9, " ", C10) -> HAG - Inputs - In Euro millions
A4: Company related inputs
E5: Scenarios | H5: Inputs/Assumptions to be altered | K5: Revenue & Expenses: | P5: Fixed Asset Forecast: | T5: Working Capital: | Y5: Debt & Cash: | AC5: Version:
B6: Company Name | C6: Hensoldt AG | E6: 1 is the most pessimistic assumption
B7: Company short Name | C7: HAG | E7: 2 is a realistic asumption | K7: Revenue Conversion Rate | N7: 3 | P7: Capex | R7: 3 | T7: Inventories | W7: 3 | Y7: Debt Policy | AA7: 1
B8: Latest financial year end | C8: 45657 | E8: 3 is the optimistic forecast | K8: Revenue Growth Rate | N8: 3 | P8: D&A | R8: 3 | Y8: Dividend Policy | AA8: 1 | AB8: <- | AC8: 2
B9: Currency | C9: Euro | E9: 4 is - if available - companies own guidance | K9: Book to Bill Ratio | N9: 3 | P9: Disposals | R9: 3 | T9: Trade Recievables | W9: 3 | Y9: Intrest Income Scenario | AA9: 2
B10: Units | C10: millions | K10: Cost of Sales | N10: 4 | T10: Contract Assets | W10: 3 | Y10: Intrest Expense Scenario | AA10: 2
K11: SG&A | N11: 3 | T11: Trade Payable | W11: 3 | Y11: Main Intrest Rate | AA11: 4
K12: R&D | N12: 3 | T12: Contract Liabilites | W12: 3
B13: Implied Share Price 1 | C13: ='DCF Valuation '!E44 -> 61.208704 | D13: €/share | E13: (Using Terminal Value) | K13: Other Income | N13: 3 | Y13: Target Levrage ratio | AA13: 2
T14: Other current assets | W14: 3 | Y14: Deffered Tax Liabilities | AA14: 1
B15: Implied Share Price 2 | C15: ='DCF Valuation '!K44 -> 48.726513 | D15: €/share | E15: (Using Exit Multiple) | T15: Other Current Liabilities | W15: 3 | Y15: Provisions % of Revenue | AA15: 0.3
T16: Other Non-current Liabiltiy | W16: 2 | Y16: Intrest rate Spread (Leases) | AA16: 0.0283
Y17: Intrest rate Spead (Debt) | AA17: 0.0175
Y18: Minimum Cash reserce | AA18: 0.3

Sheet IS Neu
A1: =_xlfn.CONCAT(Inputs!C7, " - ", "Income Statement", " - ", "in ", Inputs!C9, " ", Inputs!C10) -> HAG - Income Statement - in Euro millions
B4: Financial year end | D4: =EDATE(Inputs!$C$8, D5*12) -> 43830 | E4: =EDATE(Inputs!$C$8, E5*12) -> 44196 | F4: =EDATE(Inputs!$C$8, F5*12) -> 44561 | G4: =EDATE(Inputs!$C$8, G5*12) -> 44926 | H4: =EDATE(Inputs!$C$8, H5*12) -> 45291 | I4: =EDATE(Inputs!$C$8, I5*12) -> 45657 | J4: =EDATE(Inputs!$C$8, J5*12) -> 46022 | K4: =EDATE(Inputs!$C$8, K5*12) -> 46387 | ... N4: =EDATE(Inputs!$C$8, N5*12) -> 47483 | P4: Assumptions & Relevant Data Points
B5: Time-line counter | D5: -5 | E5: -4 | F5: -3 | G5: -2 | H5: -1 | I5: 0 | J5: 1 | K5: 2 | L5: 3 | M5: 4 | N5: 5 | P5: Tax:
B6: Currency and units | D6: =_xlfn.CONCAT(Inputs!$C$9, " ", Inputs!$C$10) -> Euro millions | E6: =_xlfn.CONCAT(Inputs!$C$9, " ", Inputs!$C$10) -> Euro millions | F6: =_xlfn.CONCAT(Inputs!$C$9, " ", Inputs!$C$10) -> Euro millions | G6: =_xlfn.CONCAT(Inputs!$C$9, " ", Inputs!$C$10) -> Euro millions | H6: =_xlfn.CONCAT(Inputs!$C$9, " ", Inputs!$C$10) -> Euro millions | I6: =_xlfn.CONCAT(Inputs!$C$9, " ", Inputs!$C$10) -> Euro millions | J6: =_xlfn.CONCAT(Inputs!$C$9, " ", Inputs!$C$10) -> Euro millions | K6: =_xlfn.CONCAT(Inputs!$C$9, " ", Inputs!$C$10) -> Euro millions | ... N6: =_xlfn.CONCAT(Inputs!$C$9, " ", Inputs!$C$10) -> Euro millions | P6: Tax Rate as shown in Annual report is on average 28,3% in Germany,
B7: Time-Stamp | D7: =IF(D5<=0, "Historical", "Forecasted") -> Historical | E7: =IF(E5<=0, "Historical", "Forecasted") -> Historical | F7: =IF(F5<=0, "Historical", "Forecasted") -> Historical | G7: =IF(G5<=0, "Historical", "Forecasted") -> Historical | H7: =IF(H5<=0, "Historical", "Forecasted") -> Historical | I7: =IF(I5<=0, "Historical", "Forecasted") -> Historical | J7: =IF(J5<=0, "Historical", "Forecasted") -> Forecasted | K7: =IF(K5<=0, "Historical", "Forecasted") -> Forecasted | ... N7: =IF(N5<=0, "Historical", "Forecasted") -> Forecasted | P7: used here to forecast the income tax burden with deferred taxed being used in 2024 to reduce the tax burden
P8: Subsidiaries in foreign countries are taxed individually, making overall taxation difficult to forecast
B9: Standardised Income Statement
P10: Other Non-Op. Income:
B11: Top Line & Gross Profit | P11: Other Non-Operating Income kept at 0 due to small impact/discretionary nature
B12: Revenue | D12: =SUMIF($J$40:$J$61,$B$12,D40:D61) -> 1114.2 | E12: =SUMIF($J$40:$J$61,$B$12,E40:E61) -> 1206.9 | F12: =SUMIF($J$40:$J$61,$B$12,F40:F61) -> 1474 | G12: =SUMIF($J$40:$J$61,$B$12,G40:G61) -> 1707 | H12: =SUMIF($J$40:$J$61,$B$12,H40:H61) -> 1847 | I12: =SUMIF($J$40:$J$61,$B$12,I40:I61) -> 2240 | J12: ='Revenue & Expenses (updated)'!M22 -> 2800 | K12: ='Revenue & Expenses (updated)'!N22 -> 2930.004 | L12: ='Revenue & Expenses (updated)'!O22 -> 3662.0577 | M12: ='Revenue & Expenses (updated)'!P22 -> 4236.7788 | N12: ='Revenue & Expenses (updated)'!Q22 -> 5090.2078
B13: Cost of Sales (COGS) | D13: =SUMIF($J$40:$J$61,$B$13,D40:D61) -> -859.3 | E13: =SUMIF($J$40:$J$61,$B$13,E40:E61) -> -936.1 | F13: =SUMIF($J$40:$J$61,$B$13,F40:F61) -> -1144 | G13: =SUMIF($J$40:$J$61,$B$13,G40:G61) -> -1314 | H13: =SUMIF($J$40:$J$61,$B$13,H40:H61) -> -1427 | I13: =SUMIF($J$40:$J$61,$B$13,I40:I61) -> -1732 | J13: ='Revenue & Expenses (updated)'!M45*-1 -> -1960 | K13: ='Revenue & Expenses (updated)'!N45*-1 -> -2021.7028 | L13: ='Revenue & Expenses (updated)'!O45*-1 -> -2490.1992 | M13: ='Revenue & Expenses (updated)'!P45*-1 -> -2881.0096 | N13: ='Revenue & Expenses (updated)'!Q45*-1 -> -3461.3413 | P13: Other Financial Net
B14: Gross Profit | D14: =SUM(D12:D13) -> 254.9 | E14: =SUM(E12:E13) -> 270.8 | F14: =SUM(F12:F13) -> 330 | G14: =SUM(G12:G13) -> 393 | H14: =SUM(H12:H13) -> 420 | I14: =SUM(I12:I13) -> 508 | J14: =SUM(J12:J13) -> 840 | K14: =SUM(K12:K13) -> 908.30124 | ... N14: =SUM(N12:N13) -> 1628.8665 | P14: Also kept at 0, since those are miscallanious items which dont have a large impact but are difficult to forecast
B15: SG&A | D15: =SUMIF($J$40:$J$61,$B$15,D40:D61) -> -161.1 | E15: =SUMIF($J$40:$J$61,$B$15,E40:E61) -> -177.4 | F15: =SUMIF($J$40:$J$61,$B$15,F40:F61) -> -182 | G15: =SUMIF($J$40:$J$61,$B$15,G40:G61) -> -199 | H15: =SUMIF($J$40:$J$61,$B$15,H40:H61) -> -229 | I15: =SUMIF($J$40:$J$61,$B$15,I40:I61) -> -290 | J15: ='Revenue & Expenses (updated)'!M47*-1 -> -252 | K15: ='Revenue & Expenses (updated)'!N47*-1 -> -263.70036 | L15: ='Revenue & Expenses (updated)'!O47*-1 -> -329.58519 | M15: ='Revenue & Expenses (updated)'!P47*-1 -> -381.31009 | N15: ='Revenue & Expenses (updated)'!Q47*-1 -> -458.1187
B16: R&D | D16: =SUMIF($J$40:$J$61,$B$16,D40:D61) -> -31 | E16: =SUMIF($J$40:$J$61,$B$16,E40:E61) -> -25.1 | F16: =SUMIF($J$40:$J$61,$B$16,F40:F61) -> -31 | G16: =SUMIF($J$40:$J$61,$B$16,G40:G61) -> -36 | H16: =SUMIF($J$40:$J$61,$B$16,H40:H61) -> -30 | I16: =SUMIF($J$40:$J$61,$B$16,I40:I61) -> -32 | J16: ='Revenue & Expenses (updated)'!M49*-1 -> -112 | K16: ='Revenue & Expenses (updated)'!N49*-1 -> -117.20016 | L16: ='Revenue & Expenses (updated)'!O49*-1 -> -146.48231 | M16: ='Revenue & Expenses (updated)'!P49*-1 -> -169.47115 | N16: ='Revenue & Expenses (updated)'!Q49*-1 -> -203.60831
B17: Other Operating Income/(Expense) Net | D17: =SUMIF($J$40:$J$61,$B$17,D40:D61) -> -0.7 | E17: =SUMIF($J$40:$J$61,$B$17,E40:E61) -> 0.2 | F17: =SUMIF($J$40:$J$61,$B$17,F40:F61) -> 9 | G17: =SUMIF($J$40:$J$61,$B$17,G40:G61) -> 8 | H17: =SUMIF($J$40:$J$61,$B$17,H40:H61) -> 6 | I17: =SUMIF($J$40:$J$61,$B$17,I40:I61) -> -2 | J17: 0 | K17: 0 | L17: 0 | M17: 0 | N17: 0
B18: EBIT | D18: =SUM(D14:D17) -> 62.1 | E18: =SUM(E14:E17) -> 68.5 | F18: =SUM(F14:F17) -> 126 | G18: =SUM(G14:G17) -> 166 | H18: =SUM(H14:H17) -> 167 | I18: =SUM(I14:I17) -> 184 | J18: =SUM(J14:J17) -> 476 | K18: =SUM(K14:K17) -> 527.40072 | ... N18: =SUM(N14:N17) -> 967.13948
B19: Interest Expense | D19: =SUMIF($J$40:$J$61,$B$19,D40:D61) -> -83.5 | E19: =SUMIF($J$40:$J$61,$B$19,E40:E61) -> -137.7 | F19: =SUMIF($J$40:$J$61,$B$19,F40:F61) -> -42 | G19: =SUMIF($J$40:$J$61,$B$19,G40:G61) -> -44 | H19: =SUMIF($J$40:$J$61,$B$19,H40:H61) -> -82 | I19: =SUMIF($J$40:$J$61,$B$19,I40:I61) -> -100 | J19: ='Debt & Cash'!K44 -> -60.20552 | K19: ='Debt & Cash'!L44 -> -76.780831 | L19: ='Debt & Cash'!M44 -> -79.521158 | M19: ='Debt & Cash'!N44 -> -66.743713 | N19: ='Debt & Cash'!O44 -> -72.503619
B20: Interest Income | D20: =SUMIF($J$40:$J$61,$B$20,D40:D61) -> 58.9 | E20: =SUMIF($J$40:$J$61,$B$20,E40:E61) -> 4 | F20: =SUMIF($J$40:$J$61,$B$20,F40:F61) -> 4 | G20: =SUMIF($J$40:$J$61,$B$20,G40:G61) -> 9 | H20: =SUMIF($J$40:$J$61,$B$20,H40:H61) -> 18 | I20: =SUMIF($J$40:$J$61,$B$20,I40:I61) -> 31 | J20: ='Debt & Cash'!K51 -> 29.66 | K20: ='Debt & Cash'!L51 -> 31.383815 | L20: ='Debt & Cash'!M51 -> 32.048631 | M20: ='Debt & Cash'!N51 -> 37.291034 | N20: ='Debt & Cash'!O51 -> 42.379228
B21: Other Fin Net | D21: =SUMIF($J$40:$J$61,$B$21,D40:D61) -> -1.9 | E21: =SUMIF($J$40:$J$61,$B$21,E40:E61) -> -10 | F21: =SUMIF($J$40:$J$61,$B$21,F40:F61) -> -3 | G21: =SUMIF($J$40:$J$61,$B$21,G40:G61) -> -1 | H21: =SUMIF($J$40:$J$61,$B$21,H40:H61) -> -7 | I21: =SUMIF($J$40:$J$61,$B$21,I40:I61) -> 1 | J21: 0 | K21: 0 | L21: 0 | M21: 0 | N21: 0
B22: EBT | D22: =SUM(D18:D21) -> 35.6 | E22: =SUM(E18:E21) -> -75.2 | F22: =SUM(F18:F21) -> 85 | G22: =SUM(G18:G21) -> 130 | H22: =SUM(H18:H21) -> 96 | I22: =SUM(I18:I21) -> 116 | J22: =SUM(J18:J21) -> 445.45448 | K22: =SUM(K18:K21) -> 482.0037 | ... N22: =SUM(N18:N21) -> 937.01509
B23: Income Taxes | C23: 0.283 | D23: =SUMIF($J$40:$J$61,$B$23,D40:D61) -> -27.4 | E23: =SUMIF($J$40:$J$61,$B$23,E40:E61) -> 10.7 | F23: =SUMIF($J$40:$J$61,$B$23,F40:F61) -> -22 | G23: =SUMIF($J$40:$J$61,$B$23,G40:G61) -> -49 | H23: =SUMIF($J$40:$J$61,$B$23,H40:H61) -> -36 | I23: =SUMIF($J$40:$J$61,$B$23,I40:I61) -> -12 | J23: =J22*$C$23*-1 -> -126.06362 | K23: =K22*$C$23*-1 -> -136.40705 | L23: =L22*$C$23*-1 -> -183.47412 | M23: =M22*$C$23*-1 -> -219.47649 | N23: =N22*$C$23*-1 -> -265.17527
B24: Net Income | D24: =SUM(D22:D23) -> 8.2 | E24: =SUM(E22:E23) -> -64.5 | F24: =SUM(F22:F23) -> 63 | G24: =SUM(G22:G23) -> 81 | H24: =SUM(H22:H23) -> 60 | I24: =SUM(I22:I23) -> 104 | J24: =J22+J23 -> 319.39086 | K24: =K22+K23 -> 345.59666 | L24: =L22+L23 -> 464.84432 | M24: =M22+M23 -> 556.05881 | N24: =N22+N23 -> 671.83982
B25: Attributable to Owners | D25: =SUMIF($J$40:$J$61,$B$25,D40:D61) -> 5.9 | E25: =SUMIF($J$40:$J$61,$B$25,E40:E61) -> -65.2 | F25: =SUMIF($J$40:$J$61,$B$25,F40:F61) -> 63 | G25: =SUMIF($J$40:$J$61,$B$25,G40:G61) -> 78 | H25: =SUMIF($J$40:$J$61,$B$25,H40:H61) -> 56 | I25: =SUMIF($J$40:$J$61,$B$25,I40:I61) -> 108 | J25: =J24-2 -> 317.39086 | K25: =K24-2 -> 343.59666 | L25: =L24-2 -> 462.84432 | M25: =M24-2 -> 554.05881 | N25: =N24-2 -> 669.83982 | P25: Non-Controlling Interest:
B26: Attributable to NCI | D26: =SUMIF($J$40:$J$61,$B$26,D40:D61) -> 2.3 | E26: =SUMIF($J$40:$J$61,$B$26,E40:E61) -> 0.7 | F26: =SUMIF($J$40:$J$61,$B$26,F40:F61) -> 0 | G26: =SUMIF($J$40:$J$61,$B$26,G40:G61) -> 2 | H26: =SUMIF($J$40:$J$61,$B$26,H40:H61) -> 2 | I26: =SUMIF($J$40:$J$61,$B$26,I40:I61) -> -2 | J26: 2 | K26: 2 | L26: 2 | M26: 2 | N26: 2 | P26: 30% SA; 6,7% US; 15% FR; 9,4% DE are non-controlling interest in Subsidiaries
B27: Per Share | D27: =D28 -> 0.07 | E27: =E28 -> -0.75 | F27: =F28 -> 0.6 | G27: =G28 -> 0.75 | H27: =H28 -> 0.53 | I27: =I28 -> 0.93 | J27: =J24/$C$28 -> 2.7533695 | K27: =K24/$C$28 -> 2.9792815 | L27: =L24/$C$28 -> 4.0072786 | M27: =M24/$C$28 -> 4.7936104 | N27: =N24/$C$28 -> 5.7917226 | P27: since the Holding company is 25% owned by Leonardo, 25% German Government and 50% Float, 2 mn as an average of the past years is assumed
B28: Earnings Per Share (EPS) Number of Shares: | C28: 116 | D28: =D61 -> 0.07 | E28: =E61 -> -0.75 | F28: =F61 -> 0.6 | G28: =G61 -> 0.75 | H28: =H61 -> 0.53 | I28: =I61 -> 0.93
P29: EBITDA:
B30: EBITDA | D30: =SUM(D18, D31) -> 191.7 | E30: =SUM(E18, E31) -> 189.3 | F30: =SUM(F18, F31) -> 252 | G30: =SUM(G18, G31) -> 269 | H30: =SUM(H18, H31) -> 284 | I30: =SUM(I18, I31) -> 346 | J30: =SUM(J18, J31) -> 739.0373 | K30: =SUM(K18, K31) -> 798.39069 | ... N30: =SUM(N18, N31) -> 1286.7258 | P30: For final calculation, the calculated EBIT needs to be adjusted by the D&A.
B31: D&A | D31: ='CF Neu '!G53 -> 129.6 | E31: ='CF Neu '!H53 -> 120.8 | F31: ='CF Neu '!I53 -> 126 | G31: ='CF Neu '!J53 -> 103 | H31: ='CF Neu '!K53 -> 117 | I31: ='CF Neu '!L53 -> 162 | J31: ='FA-Forecast (updated)'!M84 -> 263.0373 | K31: ='FA-Forecast (updated)'!N84 -> 270.98997 | L31: ='FA-Forecast (updated)'!O84 -> 279.6455 | M31: ='FA-Forecast (updated)'!P84 -> 296.85834 | N31: ='FA-Forecast (updated)'!Q84 -> 319.58634
B33: Margin (EBITDA) | D33: =D30/D12 -> 0.1720517 | E33: =E30/E12 -> 0.15684812 | F33: =F30/F12 -> 0.17096336 | G33: =G30/G12 -> 0.15758641 | H33: =H30/H12 -> 0.15376286 | I33: =I30/I12 -> 0.15446429 | J33: =J30/J12 -> 0.26394189 | K33: =K30/K12 -> 0.27248792 | ... N33: =N30/N12 -> 0.25278454
B36: Cash | D36: ='BS Neu'!D26 -> 137.4 | E36: ='BS Neu'!E26 -> 645.5 | F36: ='BS Neu'!F26 -> 529 | G36: ='BS Neu'!G26 -> 460 | H36: ='BS Neu'!H26 -> 802 | I36: ='BS Neu'!I26 -> 733 | J36: ='BS Neu'!J26 -> 936.21801 | K36: ='BS Neu'!K26 -> 1136.5754 | ... N36: ='BS Neu'!N26 -> 2223.6018
B37: Cash Safety lvl | D37: =D36/D12 -> 0.12331718 | E37: =E36/E12 -> 0.53484133 | F37: =F36/F12 -> 0.35888738 | G37: =G36/G12 -> 0.26947862 | H37: =H36/H12 -> 0.43421765 | I37: =I36/I12 -> 0.32723214 | J37: =J36/J12 -> 0.33436357 | K37: =K36/K12 -> 0.38790916 | ... N37: =N36/N12 -> 0.43683911
B39: Year | D39: 2019 | E39: 2020 | F39: 2021 | G39: 2022 | H39: 2023 | I39: 2024
B40: Revenue | D40: 1114.2 | E40: 1206.9 | F40: 1474 | G40: 1707 | H40: 1847 | I40: 2240 | J40: Revenue
B41: Cost of sales | D41: -859.3 | E41: -936.1 | F41: -1144 | G41: -1314 | H41: -1427 | I41: -1732 | J41: Cost of Sales (COGS)
B42: Gross profit | D42: 254.9 | E42: 270.8 | F42: 330 | G42: 393 | H42: 420 | I42: 508 | J42: Gross Profit
B43: Selling and distribution expenses | D43: -84.8 | E43: -90.2 | F43: -99 | G43: -107 | H43: -111 | I43: -128 | J43: SG&A
B44: General administrative expenses | D44: -76.3 | E44: -87.2 | F44: -83 | G44: -92 | H44: -118 | I44: -162 | J44: SG&A
B45: Research and development costs | D45: -31 | E45: -25.1 | F45: -31 | G45: -36 | H45: -30 | I45: -32 | J45: R&D
B46: Other operating income | D46: 25.3 | E46: 18.9 | F46: 29 | G46: 21 | H46: 22 | I46: 22 | J46: Other Operating Income/(Expense) Net
...

Sheet BS Neu
A1: =_xlfn.CONCAT(Inputs!C7, " - ", "Balance Sheet", " - ", "in ", Inputs!C9, " ", Inputs!C10) -> HAG - Balance Sheet - in Euro millions
B4: Financial year end | D4: =EDATE(Inputs!$C$8, D5*12) -> 43830 | E4: =EDATE(Inputs!$C$8, E5*12) -> 44196 | F4: =EDATE(Inputs!$C$8, F5*12) -> 44561 | G4: =EDATE(Inputs!$C$8, G5*12) -> 44926 | H4: =EDATE(Inputs!$C$8, H5*12) -> 45291 | I4: =EDATE(Inputs!$C$8, I5*12) -> 45657 | J4: =EDATE(Inputs!$C$8, J5*12) -> 46022 | K4: =EDATE(Inputs!$C$8, K5*12) -> 46387 | ... N4: =EDATE(Inputs!$C$8, N5*12) -> 47483
B5: Time-line counter | D5: -5 | E5: -4 | F5: -3 | G5: -2 | H5: -1 | I5: 0 | J5: 1 | K5: 2 | L5: 3 | M5: 4 | N5: 5
B6: Currency and units | D6: =_xlfn.CONCAT(Inputs!$C$9, " ", Inputs!$C$10) -> Euro millions | E6: =_xlfn.CONCAT(Inputs!$C$9, " ", Inputs!$C$10) -> Euro millions | F6: =_xlfn.CONCAT(Inputs!$C$9, " ", Inputs!$C$10) -> Euro millions | G6: =_xlfn.CONCAT(Inputs!$C$9, " ", Inputs!$C$10) -> Euro millions | H6: =_xlfn.CONCAT(Inputs!$C$9, " ", Inputs!$C$10) -> Euro millions | I6: =_xlfn.CONCAT(Inputs!$C$9, " ", Inputs!$C$10) -> Euro millions | J6: =_xlfn.CONCAT(Inputs!$C$9, " ", Inputs!$C$10) -> Euro millions | K6: =_xlfn.CONCAT(Inputs!$C$9, " ", Inputs!$C$10) -> Euro millions | ... N6: =_xlfn.CONCAT(Inputs!$C$9, " ", Inputs!$C$10) -> Euro millions
B7: Time-Stamp | D7: =IF(D5<=0, "Historical", "Forecasted") -> Historical | E7: =IF(E5<=0, "Historical", "Forecasted") -> Historical | F7: =IF(F5<=0, "Historical", "Forecasted") -> Historical | G7: =IF(G5<=0, "Historical", "Forecasted") -> Historical | H7: =IF(H5<=0, "Historical", "Forecasted") -> Historical | I7: =IF(I5<=0, "Historical", "Forecasted") -> Historical | J7: =IF(J5<=0, "Historical", "Forecasted") -> Forecasted | K7: =IF(K5<=0, "Historical", "Forecasted") -> Forecasted | ... N7: =IF(N5<=0, "Historical", "Forecasted") -> Forecasted
B10: Standardised Balance sheet
B12: Assets
B13: Non-Current Assets
A14: x | B14: Goodwill & Intangibles | D14: =SUMIF($J$66:$J$111, $B$14,D66:D111) -> 1040.5 | E14: =SUMIF($J$66:$J$111, $B$14,E66:E111) -> 1023.4 | F14: =SUMIF($J$66:$J$111, $B$14,F66:F111) -> 1043 | G14: =SUMIF($J$66:$J$111, $B$14,G66:G111) -> 1042 | H14: =SUMIF($J$66:$J$111, $B$14,H66:H111) -> 1057 | I14: =SUMIF($J$66:$J$111, $B$14,I66:I111) -> 1782 | J14: ='FA-Forecast (updated)'!M41 -> 1766.6493 | K14: ='FA-Forecast (updated)'!N41 -> 1746.7553 | L14: ='FA-Forecast (updated)'!O41 -> 1756.9797 | M14: ='FA-Forecast (updated)'!P41 -> 1784.8072 | N14: ='FA-Forecast (updated)'!Q41 -> 1840.4171
A15: x | B15: Property, Plant & Equipment (incl. RoU) | D15: =SUMIF($J$66:$J$111, $B$15, D66:D111) -> 247.8 | E15: =SUMIF($J$66:$J$111, $B$15, E66:E111) -> 246.6 | F15: =SUMIF($J$66:$J$111, $B$15, F66:F111) -> 249 | G15: =SUMIF($J$66:$J$111, $B$15, G66:G111) -> 261 | H15: =SUMIF($J$66:$J$111, $B$15, H66:H111) -> 329 | I15: =SUMIF($J$66:$J$111, $B$15, I66:I111) -> 451 | J15: ='FA-Forecast (updated)'!M51 -> 624.16865 | K15: ='FA-Forecast (updated)'!N51 -> 722.74923 | L15: ='FA-Forecast (updated)'!O51 -> 869.00526 | M15: ='FA-Forecast (updated)'!P51 -> 1047.7959 | N15: ='FA-Forecast (updated)'!Q51 -> 1276.6266
B16: Investments & Other Fin Assets (NC) | D16: =SUMIF($J$66:$J$111, $B$16, D66:D111) -> 69.1 | E16: =SUMIF($J$66:$J$111, $B$16, E66:E111) -> 12.3 | F16: =SUMIF($J$66:$J$111, $B$16, F66:F111) -> 22 | G16: =SUMIF($J$66:$J$111, $B$16, G66:G111) -> 24 | H16: =SUMIF($J$66:$J$111, $B$16, H66:H111) -> 26 | I16: =SUMIF($J$66:$J$111, $B$16, I66:I111) -> 35 | J16: =I16 -> 35 | K16: =J16 -> 35 | L16: =K16 -> 35 | M16: =L16 -> 35 | N16: =M16 -> 35 | O16: (Kept constant, since there is no clear indication if the company intends to increase/decrease this)
B17: Other Non-Current Assets | D17: =SUMIF($J$66:$J$111, $B$17, D66:D111) -> 4.9 | E17: =SUMIF($J$66:$J$111, $B$17, E66:E111) -> 4.8 | F17: =SUMIF($J$66:$J$111, $B$17, F66:F111) -> 3 | G17: =SUMIF($J$66:$J$111, $B$17, G66:G111) -> 2 | H17: =SUMIF($J$66:$J$111, $B$17, H66:H111) -> 3 | I17: =SUMIF($J$66:$J$111, $B$17, I66:I111) -> 20 | J17: ='BS Neu'!I17 -> 20 | K17: ='BS Neu'!J17 -> 20 | L17: ='BS Neu'!K17 -> 20 | M17: ='BS Neu'!L17 -> 20 | N17: ='BS Neu'!M17 -> 20
B18: Deferred Tax Assets | D18: =SUMIF($J$66:$J$111, $B$18, D66:D111) -> 30.4 | E18: =SUMIF($J$66:$J$111, $B$18, E66:E111) -> 26.3 | F18: =SUMIF($J$66:$J$111, $B$18, F66:F111) -> 11 | G18: =SUMIF($J$66:$J$111, $B$18, G66:G111) -> 6 | H18: =SUMIF($J$66:$J$111, $B$18, H66:H111) -> 9 | I18: =SUMIF($J$66:$J$111, $B$18, I66:I111) -> 1 | J18: 0 | K18: 0 | L18: 0 | M18: 0 | N18: 0
B19: Total Non-Current Assets | D19: =SUM(D14:D18) -> 1392.7 | E19: =SUM(E14:E18) -> 1313.4 | F19: =SUM(F14:F18) -> 1328 | G19: =SUM(G14:G18) -> 1335 | H19: =SUM(H14:H18) -> 1424 | I19: =SUM(I14:I18) -> 2289 | J19: =SUM(J13:J18) -> 2445.8179 | K19: =SUM(K13:K18) -> 2524.5045 | L19: =SUM(L13:L18) -> 2680.9849 | M19: =SUM(M13:M18) -> 2887.6031 | N19: =SUM(N13:N18) -> 3172.0437
B21: Current Assets
A22: x | B22: Inventories | D22: =SUMIF($J$66:$J$111, $B$22,D66:D111) -> 411.1 | E22: =SUMIF($J$66:$J$111, $B$22,E66:E111) -> 403.7 | F22: =SUMIF($J$66:$J$111, $B$22,F66:F111) -> 444 | G22: =SUMIF($J$66:$J$111, $B$22,G66:G111) -> 516 | H22: =SUMIF($J$66:$J$111, $B$22,H66:H111) -> 625 | I22: =SUMIF($J$66:$J$111, $B$22,I66:I111) -> 719 | J22: ='WC & other Assets (updated) '!M16 -> 751.78082 | K22: ='WC & other Assets (updated) '!N16 -> 775.44763 | L22: ='WC & other Assets (updated) '!O16 -> 955.14491 | M22: ='WC & other Assets (updated) '!P16 -> 1105.0448 | N22: ='WC & other Assets (updated) '!Q16 -> 1327.6378
A23: x | B23: Trade Receivables | D23: =SUMIF($J$66:$J$111, $B$23,D66:D111) -> 290.8 | E23: =SUMIF($J$66:$J$111, $B$23,E66:E111) -> 282 | F23: =SUMIF($J$66:$J$111, $B$23,F66:F111) -> 309 | G23: =SUMIF($J$66:$J$111, $B$23,G66:G111) -> 323 | H23: =SUMIF($J$66:$J$111, $B$23,H66:H111) -> 382 | I23: =SUMIF($J$66:$J$111, $B$23,I66:I111) -> 426 | J23: ='WC & other Assets (updated) '!M25 -> 421.91781 | K23: ='WC & other Assets (updated) '!N25 -> 441.50745 | L23: ='WC & other Assets (updated) '!O25 -> 551.81691 | M23: ='WC & other Assets (updated) '!P25 -> 638.41873 | N23: ='WC & other Assets (updated) '!Q25 -> 767.01761
B24: Contract Assets | D24: =SUMIF($J$66:$J$111, $B$24,D66:D111) -> 165.9 | E24: =SUMIF($J$66:$J$111, $B$24,E66:E111) -> 204.4 | F24: =SUMIF($J$66:$J$111, $B$24,F66:F111) -> 170 | G24: =SUMIF($J$66:$J$111, $B$24,G66:G111) -> 182 | H24: =SUMIF($J$66:$J$111, $B$24,H66:H111) -> 196 | I24: =SUMIF($J$66:$J$111, $B$24,I66:I111) -> 385 | J24: ='WC & other Assets (updated) '!M23 -> 308 | K24: ='WC & other Assets (updated) '!N23 -> 322.30044 | L24: ='WC & other Assets (updated) '!O23 -> 402.82635 | M24: ='WC & other Assets (updated) '!P23 -> 466.04567 | N24: ='WC & other Assets (updated) '!Q23 -> 559.92286
B25: Other Current Assets | D25: =SUMIF($J$66:$J$111, $B$25,D66:D111) -> 58.1 | E25: =SUMIF($J$66:$J$111, $B$25,E66:E111) -> 98.6 | F25: =SUMIF($J$66:$J$111, $B$25,F66:F111) -> 177 | G25: =SUMIF($J$66:$J$111, $B$25,G66:G111) -> 163 | H25: =SUMIF($J$66:$J$111, $B$25,H66:H111) -> 150 | I25: =SUMIF($J$66:$J$111, $B$25,I66:I111) -> 143 | J25: ='Debt & Cash'!K107+'WC & other Assets (updated) '!M70 -> 301.38087 | K25: ='Debt & Cash'!L107+'WC & other Assets (updated) '!N70 -> 315.37399 | L25: ='Debt & Cash'!M107+'WC & other Assets (updated) '!O70 -> 394.16934 | M25: ='Debt & Cash'!N107+'WC & other Assets (updated) '!P70 -> 456.03004 | N25: ='Debt & Cash'!O107+'WC & other Assets (updated) '!Q70 -> 547.88974
B26: Cash & Cash Equivalents | D26: =SUMIF($J$66:$J$111, $B$26,D66:D111) -> 137.4 | E26: =SUMIF($J$66:$J$111, $B$26,E66:E111) -> 645.5 | F26: =SUMIF($J$66:$J$111, $B$26,F66:F111) -> 529 | G26: =SUMIF($J$66:$J$111, $B$26,G66:G111) -> 460 | H26: =SUMIF($J$66:$J$111, $B$26,H66:H111) -> 802 | I26: =SUMIF($J$66:$J$111, $B$26,I66:I111) -> 733 | J26: =I26+'CF Neu '!M38 -> 936.21801 | K26: =J26+'CF Neu '!N38 -> 1136.5754 | L26: =K26+'CF Neu '!O38 -> 1486.0689 | M26: =L26+'CF Neu '!P38 -> 1825.2819 | N26: =M26+'CF Neu '!Q38 -> 2223.6018 | O26: (THIS IS A PLUG, which will be balanced through the other items. Not forecasted as a %)
B27: Total Current Assets | D27: =SUM(D22:D26) -> 1063.3 | E27: =SUM(E22:E26) -> 1634.2 | F27: =SUM(F22:F26) -> 1629 | G27: =SUM(G22:G26) -> 1644 | H27: =SUM(H22:H26) -> 2155 | I27: =SUM(I22:I26) -> 2406 | J27: =SUM(J22:J26) -> 2719.2975 | K27: =SUM(K22:K26) -> 2991.2049 | ... N27: =SUM(N22:N26) -> 5426.0698 | O27: (Cash is not forecasted but a result of the Cash-Flow Statement Result)
B29: Total Assets | D29: =SUM(D27,D19) -> 2456 | E29: =SUM(E27,E19) -> 2947.6 | F29: =SUM(F27,F19) -> 2957 | G29: =SUM(G27,G19) -> 2979 | H29: =SUM(H27,H19) -> 3579 | I29: =SUM(I27,I19) -> 4695 | J29: =SUM(J27,J19) -> 5165.1154 | K29: =SUM(K27,K19) -> 5515.7094 | ... N29: =SUM(N27,N19) -> 8598.1135
B31: Equity & Liab.
B32: Equity
A33: x | B33: Share Capital | D33: =SUMIF($J$66:$J$112, $B$33, D66:D112) -> 10 | E33: =SUMIF($J$66:$J$112, $B$33, E66:E112) -> 105 | F33: =SUMIF($J$66:$J$112, $B$33, F66:F112) -> 105 | G33: =SUMIF($J$66:$J$112, $B$33, G66:G112) -> 105 | H33: =SUMIF($J$66:$J$112, $B$33, H66:H112) -> 116 | I33: =SUMIF($J$66:$J$112, $B$33, I66:I112) -> 116 | J33: 116 | K33: 116 | L33: 116 | M33: 116 | N33: 116 | O33: (Kept Constant (no capital markets financing -> strong financial position)
B34: Other Reserves (incl. Capital Reserve) | D34: =SUMIF($J$66:$J$112,$B$34, D66:D112) -> 346.9 | E34: =SUMIF($J$66:$J$112,$B$34, E66:E112) -> 510.5 | F34: =SUMIF($J$66:$J$112,$B$34, F66:F112) -> 472 | G34: =SUMIF($J$66:$J$112,$B$34, G66:G112) -> 554 | H34: =SUMIF($J$66:$J$112,$B$34, H66:H112) -> 645 | I34: 508 | J34: 508 | K34: 508 | L34: 508 | M34: 508 | N34: 508 | O34: (Kept constant, since there is no indication/legal guidline forcing the company to keep more of it's excess cash in reserves)
B35: Retained Earnings | D35: =SUMIF($J$66:$J$112,$B$35,D66:D112) -> -215.8 | E35: =SUMIF($J$66:$J$112,$B$35,E66:E112) -> -281.6 | F35: =SUMIF($J$66:$J$112,$B$35,F66:F112) -> -171 | G35: =SUMIF($J$66:$J$112,$B$35,G66:G112) -> -55 | H35: =SUMIF($J$66:$J$112,$B$35,H66:H112) -> 62 | I35: 245 | J35: =I35+'IS Neu'!J24+'CF Neu '!M32 -> 427.05279 | K35: =J35+'IS Neu'!K24+'CF Neu '!N32 -> 617.13095 | L35: =K35+'IS Neu'!L24+'CF Neu '!O32 -> 863.49844 | M35: =L35+'IS Neu'!M24+'CF Neu '!P32 -> 1147.0884 | N35: =M35+'IS Neu'!N24+'CF Neu '!Q32 -> 1476.2899
B36: Equity Attributable to Shareholders | D36: =SUMIF($J$66:J$112,$B$36, D66:D112) -> 141.2 | E36: =SUMIF($J$66:K$112,$B$36, E66:E112) -> 333.9 | F36: =SUMIF($J$66:L$112,$B$36, F66:F112) -> 406 | G36: =SUMIF($J$66:M$112,$B$36, G66:G112) -> 604 | H36: =SUMIF($J$66:N$112,$B$36, H66:H112) -> 822 | I36: =SUM(I33:I35) -> 869 | J36: =SUM(J33:J35) -> 1051.0528 | K36: =SUM(K33:K35) -> 1241.131 | L36: =SUM(L33:L35) -> 1487.4984 | M36: =SUM(M33:M35) -> 1771.0884 | N36: =SUM(N33:N35) -> 2100.2899
B37: Non-Controlling Interests | D37: =SUMIF($J$66:J$112,$B$37, D66:D112) -> 13.6 | E37: =SUMIF($J$66:K$112,$B$37, E66:E112) -> 12.9 | F37: =SUMIF($J$66:L$112,$B$37, F66:F112) -> 11 | G37: =SUMIF($J$66:M$112,$B$37, G66:G112) -> 13 | H37: =SUMIF($J$66:N$112,$B$37, H66:H112) -> 16 | I37: =SUMIF($J$66:O$112,$B$37, I66:I112) -> 14 | J37: =I37 -> 14 | K37: =J37 -> 14 | L37: =K37 -> 14 | M37: =L37 -> 14 | N37: =M37 -> 14 | O37: (Kept constant, because share of other investors in subsidiaries is not likely to change. SA, FR, DE subsidiaries with other shareholders)
B38: Total Equity | D38: =SUM(D36,D37) -> 154.8 | E38: =SUM(E36,E37) -> 346.8 | F38: =SUM(F36,F37) -> 417 | G38: =SUM(G36,G37) -> 617 | H38: =SUM(H36,H37) -> 838 | I38: =SUM(I36,I37) -> 883 | J38: =SUM(J36:J37) -> 1065.0528 | K38: =SUM(K36:K37) -> 1255.131 | L38: =SUM(L36:L37) -> 1501.4984 | M38: =SUM(M36:M37) -> 1785.0884 | N38: =SUM(N36:N37) -> 2114.2899
B40: Liabilities
B41: Non-Current Liabilities
B42: Non-Current Debt (Financing & Lease) | D42: =SUMIF($J$66:J$112,$B$42, D66:D112) -> 1035.2 | E42: =SUMIF($J$66:K$112,$B$42, E66:E112) -> 741.6 | F42: =SUMIF($J$66:L$112,$B$42, F66:F112) -> 761 | G42: =SUMIF($J$66:M$112,$B$42, G66:G112) -> 759 | H42: =SUMIF($J$66:N$112,$B$42, H66:H112) -> 812 | I42: =SUMIF($J$66:O$112,$B$42, I66:I112) -> 1328 | J42: ='Debt & Cash'!K61 -> 1326.6636 | K42: ='Debt & Cash'!L61 -> 1383.0844 | L42: ='Debt & Cash'!M61 -> 1466.4356 | M42: ='Debt & Cash'!N61 -> 1566.8764 | N42: ='Debt & Cash'!O61 -> 1694.8995
B43: Non-Current Provisions | D43: =SUMIF($J$66:J$112,$B$43, D66:D112) -> 413.6 | E43: =SUMIF($J$66:K$112,$B$43, E66:E112) -> 482.6 | F43: =SUMIF($J$66:L$112,$B$43, F66:F112) -> 497 | G43: =SUMIF($J$66:M$112,$B$43, G66:G112) -> 282 | H43: =SUMIF($J$66:N$112,$B$43, H66:H112) -> 357 | I43: =SUMIF($J$66:O$112,$B$43, I66:I112) -> 418 | J43: ='Debt & Cash'!K137 -> 588 | K43: ='Debt & Cash'!L137 -> 615.30084 | L43: ='Debt & Cash'!M137 -> 769.03212 | M43: ='Debt & Cash'!N137 -> 889.72355 | N43: ='Debt & Cash'!O137 -> 1068.9436
B44: Other Non-Current Liabilities | D44: =SUMIF($J$66:J$112,$B$44, D66:D112) -> 24.2 | E44: =SUMIF($J$66:K$112,$B$44, E66:E112) -> 25.1 | F44: =SUMIF($J$66:L$112,$B$44, F66:F112) -> 22 | G44: =SUMIF($J$66:M$112,$B$44, G66:G112) -> 25 | H44: =SUMIF($J$66:N$112,$B$44, H66:H112) -> 24 | I44: =SUMIF($J$66:O$112,$B$44, I66:I112) -> 59 | J44: ='WC & other Assets (updated) '!M83 -> 45.673907 | K44: ='WC & other Assets (updated) '!N83 -> 49.994134 | L44: ='WC & other Assets (updated) '!O83 -> 68.145468 | M44: ='WC & other Assets (updated) '!P83 -> 72.406694 | N44: ='WC & other Assets (updated) '!Q83 -> 89.102537
B45: Deferred Tax Liabilities | D45: =SUMIF($J$66:J$112,$B$45, D66:D112) -> 44.9 | E45: =SUMIF($J$66:K$112,$B$45, E66:E112) -> 15.3 | F45: =SUMIF($J$66:L$112,$B$45, F66:F112) -> 15 | G45: =SUMIF($J$66:M$112,$B$45, G66:G112) -> 113 | H45: =SUMIF($J$66:N$112,$B$45, H66:H112) -> 118 | I45: =SUMIF($J$66:O$112,$B$45, I66:I112) -> 156 | J45: ='Debt & Cash'!K112 -> 182.95527 | K45: ='Debt & Cash'!L112 -> 188.84128 | L45: ='Debt & Cash'!M112 -> 200.54653 | M45: ='Debt & Cash'!N112 -> 216.00226 | N45: ='Debt & Cash'!O112 -> 237.27936 | O45: (from debt and cash scheduel, assumption is, that the historical average of total-non current assets for net deffered tax is held steady)
B46: Total Non-Current Liabilities | D46: =SUM(D42:D45) -> 1517.9 | E46: =SUM(E42:E45) -> 1264.6 | F46: =SUM(F42:F45) -> 1295 | G46: =SUM(G42:G45) -> 1179 | H46: =SUM(H42:H45) -> 1311 | I46: =SUM(I42:I45) -> 1961 | J46: =SUM(J42:J45) -> 2143.2928 | K46: =SUM(K42:K45) -> 2237.2206 | ... N46: =SUM(N42:N45) -> 3090.225
B48: Current Liabilities
B49: Current Debt (Financing & Lease) | D49: =SUMIF($J$66:$J$112,$B$49,D66:D112) -> 44.8 | E49: =SUMIF($J$66:$J$112,$B$49,E66:E112) -> 474.8 | F49: =SUMIF($J$66:$J$112,$B$49,F66:F112) -> 192 | G49: =SUMIF($J$66:$J$112,$B$49,G66:G112) -> 34 | H49: =SUMIF($J$66:$J$112,$B$49,H66:H112) -> 50 | I49: =SUMIF($J$66:$J$112,$B$49,I66:I112) -> 121 | J49: ='Debt & Cash'!K60 -> 120.9 | K49: ='Debt & Cash'!L60 -> 112.5 | L49: ='Debt & Cash'!M60 -> 112.5 | M49: ='Debt & Cash'!N60 -> 112.5 | N49: ='Debt & Cash'!O60 -> 112.5
A50: x | B50: Trade Payables | D50: =SUMIF($J$66:$J$112,$B$50,D66:D112) -> 168.8 | E50: =SUMIF($J$66:$J$112,$B$50,E66:E112) -> 164 | F50: =SUMIF($J$66:$J$112,$B$50,F66:F112) -> 269 | G50: =SUMIF($J$66:$J$112,$B$50,G66:G112) -> 379 | H50: =SUMIF($J$66:$J$112,$B$50,H66:H112) -> 457 | I50: =SUMIF($J$66:$J$112,$B$50,I66:I112) -> 546 | J50: ='WC & other Assets (updated) '!M34 -> 483.28767 | K50: ='WC & other Assets (updated) '!N34 -> 498.50205 | L50: ='WC & other Assets (updated) '!O34 -> 614.02173 | M50: ='WC & other Assets (updated) '!P34 -> 710.38593 | N50: ='WC & other Assets (updated) '!Q34 -> 853.48142
...

Sheet CF Neu 
A1: =_xlfn.CONCAT(Inputs!C7, " - ", "Cash Flow", " - ", "in ", Inputs!C9, " ", Inputs!C10) -> HAG - Cash Flow - in Euro millions
B4: Financial year end | G4: =EDATE(Inputs!$C$8, G5*12) -> 43830 | H4: =EDATE(Inputs!$C$8, H5*12) -> 44196 | I4: =EDATE(Inputs!$C$8, I5*12) -> 44561 | J4: =EDATE(Inputs!$C$8, J5*12) -> 44926 | K4: =EDATE(Inputs!$C$8, K5*12) -> 45291 | L4: =EDATE(Inputs!$C$8, L5*12) -> 45657 | M4: =EDATE(Inputs!$C$8, M5*12) -> 46022 | N4: =EDATE(Inputs!$C$8, N5*12) -> 46387 | ... Q4: =EDATE(Inputs!$C$8, Q5*12) -> 47483
B5: Time-line counter | G5: -5 | H5: -4 | I5: -3 | J5: -2 | K5: -1 | L5: 0 | M5: 1 | N5: 2 | O5: 3 | P5: 4 | Q5: 5
B6: Currency and units | G6: =_xlfn.CONCAT(Inputs!$C$9, " ", Inputs!$C$10) -> Euro millions | H6: =_xlfn.CONCAT(Inputs!$C$9, " ", Inputs!$C$10) -> Euro millions | I6: =_xlfn.CONCAT(Inputs!$C$9, " ", Inputs!$C$10) -> Euro millions | J6: =_xlfn.CONCAT(Inputs!$C$9, " ", Inputs!$C$10) -> Euro millions | K6: =_xlfn.CONCAT(Inputs!$C$9, " ", Inputs!$C$10) -> Euro millions | L6: =_xlfn.CONCAT(Inputs!$C$9, " ", Inputs!$C$10) -> Euro millions | M6: =_xlfn.CONCAT(Inputs!$C$9, " ", Inputs!$C$10) -> Euro millions | N6: =_xlfn.CONCAT(Inputs!$C$9, " ", Inputs!$C$10) -> Euro millions | ... Q6: =_xlfn.CONCAT(Inputs!$C$9, " ", Inputs!$C$10) -> Euro millions
B7: Time-Stamp | G7: =IF(G5<=0, "Historical", "Forecasted") -> Historical | H7: =IF(H5<=0, "Historical", "Forecasted") -> Historical | I7: =IF(I5<=0, "Historical", "Forecasted") -> Historical | J7: =IF(J5<=0, "Historical", "Forecasted") -> Historical | K7: =IF(K5<=0, "Historical", "Forecasted") -> Historical | L7: =IF(L5<=0, "Historical", "Forecasted") -> Historical | M7: =IF(M5<=0, "Historical", "Forecasted") -> Forecasted | N7: =IF(N5<=0, "Historical", "Forecasted") -> Forecasted | ... Q7: =IF(Q5<=0, "Historical", "Forecasted") -> Forecasted
B10: Standardised Cash Flow Statement
B14: Operating Activities
B15: Group Profit / Loss (or Net Income) | G15: =G52 -> 8.2 | H15: =H52 -> -64.5 | I15: =I52 -> 63 | J15: =J52 -> 80 | K15: =K52 -> 58 | L15: =L52 -> 106 | M15: ='IS Neu'!J24 -> 319.39086 | N15: ='IS Neu'!K24 -> 345.59666 | O15: ='IS Neu'!L24 -> 464.84432 | P15: ='IS Neu'!M24 -> 556.05881 | Q15: ='IS Neu'!N24 -> 671.83982
B16: Adjustments for Non-Cash Items | G16: =SUMIF($M$53:$M$90, $B$16, G53:G90) -> 143.2 | H16: =SUMIF($M$53:$M$90, $B$16, H53:H90) -> 118.4 | I16: =SUMIF($M$53:$M$90, $B$16, I53:I90) -> 128 | J16: =SUMIF($M$53:$M$90, $B$16, J53:J90) -> 105 | K16: =SUMIF($M$53:$M$90, $B$16, K53:K90) -> 133 | L16: =SUMIF($M$53:$M$90, $B$16, L53:L90) -> 180 | M16: ='FA-Forecast (updated)'!M84 -> 263.0373 | N16: ='FA-Forecast (updated)'!N84 -> 270.98997 | O16: ='FA-Forecast (updated)'!O84 -> 279.6455 | P16: ='FA-Forecast (updated)'!P84 -> 296.85834 | Q16: ='FA-Forecast (updated)'!Q84 -> 319.58634
B17: Change in Working Capital | G17: =SUMIF($M$53:$M$90, $B$17, G53:G90) -> -60 | H17: =SUMIF($M$53:$M$90, $B$17, H53:H90) -> 92 | I17: =SUMIF($M$53:$M$90, $B$17, I53:I90) -> 100 | J17: =SUMIF($M$53:$M$90, $B$17, J53:J90) -> 17 | K17: =SUMIF($M$53:$M$90, $B$17, K53:K90) -> 46 | L17: =SUMIF($M$53:$M$90, $B$17, L53:L90) -> 28 | M17: ='WC & other Assets (updated) '!M135 -> -44.391834 | N17: ='WC & other Assets (updated) '!N135 -> 28.520058 | O17: ='WC & other Assets (updated) '!O135 -> 154.90912 | P17: ='WC & other Assets (updated) '!P135 -> 120.53532 | Q17: ='WC & other Assets (updated) '!Q135 -> 178.98826
B18: Interest Paid (Net of Received) | G18: =SUMIF($M$53:$M$90, $B$18, G53:G90) -> -45.1 | H18: =SUMIF($M$53:$M$90, $B$18, H53:H90) -> -58.5 | I18: =SUMIF($M$53:$M$90, $B$18, I53:I90) -> -36 | J18: =SUMIF($M$53:$M$90, $B$18, J53:J90) -> -24 | K18: =SUMIF($M$53:$M$90, $B$18, K53:K90) -> -35 | L18: =SUMIF($M$53:$M$90, $B$18, L53:L90) -> -45 | M18: ='Debt & Cash'!K55 -> -30.54552 | N18: ='Debt & Cash'!L55 -> -45.397016 | O18: ='Debt & Cash'!M55 -> -47.472527 | P18: ='Debt & Cash'!N55 -> -29.452679 | Q18: ='Debt & Cash'!O55 -> -30.124391
B19: Taxes Paid (Net of Refunds) | G19: =SUMIF($M$53:$M$90, $B$19, G53:G90) -> 16.5 | H19: =SUMIF($M$53:$M$90, $B$19, H53:H90) -> -16.2 | I19: =SUMIF($M$53:$M$90, $B$19, I53:I90) -> 13 | J19: =SUMIF($M$53:$M$90, $B$19, J53:J90) -> 38 | K19: =SUMIF($M$53:$M$90, $B$19, K53:K90) -> 9 | L19: =SUMIF($M$53:$M$90, $B$19, L53:L90) -> -6 | M19: ='WC & other Assets (updated) '!M124 -> 64.393476 | N19: ='WC & other Assets (updated) '!N124 -> 7.9963319 | O19: ='WC & other Assets (updated) '!O124 -> 20.235392 | P19: ='WC & other Assets (updated) '!P124 -> 21.867847 | Q19: ='WC & other Assets (updated) '!Q124 -> 28.469928
B20: Net Cash from Operating Activities | G20: =SUM(G15:G19) -> 62.8 | H20: =SUM(H15:H19) -> 71.2 | I20: =SUM(I15:I19) -> 268 | J20: =SUM(J15:J19) -> 216 | K20: =SUM(K15:K19) -> 211 | L20: =SUM(L15:L19) -> 263 | M20: =SUM(M15:M19) -> 571.88429 | N20: =SUM(N15:N19) -> 607.706 | ... Q20: =SUM(Q15:Q19) -> 1168.76
B22: Investing Activities
B23: Capital Expenditures (Net) | G23: =SUMIF($M$53:$M$90, $B$23, G53:G90) -> -80 | H23: =SUMIF($M$53:$M$90, $B$23, H53:H90) -> -97.2 | I23: =SUMIF($M$53:$M$90, $B$23, I53:I90) -> -99 | J23: =SUMIF($M$53:$M$90, $B$23, J53:J90) -> -95 | K23: =SUMIF($M$53:$M$90, $B$23, K53:K90) -> -114 | L23: =SUMIF($M$53:$M$90, $B$23, L53:L90) -> -197 | M23: ='FA-Forecast (updated)'!M65*-1 -> -336 | N23: ='FA-Forecast (updated)'!N65*-1 -> -351.60048 | O23: ='FA-Forecast (updated)'!O65*-1 -> -439.44692 | P23: ='FA-Forecast (updated)'!P65*-1 -> -508.41346 | Q23: ='FA-Forecast (updated)'!Q65*-1 -> -610.82494
B24: Acquisitions & Investments (Net) | G24: =SUMIF($M$53:$M$90, $B$24, G53:G90) -> -85.6 | H24: =SUMIF($M$53:$M$90, $B$24, H53:H90) -> 2.1 | I24: =SUMIF($M$53:$M$90, $B$24, I53:I90) -> -19 | J24: =SUMIF($M$53:$M$90, $B$24, J53:J90) -> -6 | K24: =SUMIF($M$53:$M$90, $B$24, K53:K90) -> -9 | L24: =SUMIF($M$53:$M$90, $B$24, L53:L90) -> -547 | M24: 0 | N24: 0 | O24: 0 | P24: 0 | Q24: 0
B25: Other Investing Activities | G25: =SUMIF($M$53:$M$90, $B$25, G53:G90) -> 20.4 | H25: =SUMIF($M$53:$M$90, $B$25, H53:H90) -> 125.9 | I25: =SUMIF($M$53:$M$90, $B$25, I53:I90) -> 32 | J25: =SUMIF($M$53:$M$90, $B$25, J53:J90) -> 28 | K25: =SUMIF($M$53:$M$90, $B$25, K53:K90) -> 55 | L25: =SUMIF($M$53:$M$90, $B$25, L53:L90) -> 49 | M25: 50 | N25: 50 | O25: 50 | P25: 50 | Q25: 50 | R25: (since there is no clear indication of this changing dramatically)
B26: Net Cash from Investing Activities | G26: =SUM(G23:G25) -> -145.2 | H26: =SUM(H23:H25) -> 30.8 | I26: =SUM(I23:I25) -> -86 | J26: =SUM(J23:J25) -> -73 | K26: =SUM(K23:K25) -> -68 | L26: =SUM(L23:L25) -> -695 | M26: =SUM(M23:M25) -> -286 | N26: =SUM(N23:N25) -> -301.60048 | ... Q26: =SUM(Q23:Q25) -> -560.82494
B28: Financing Activities
B29: Net Change in Debt / Financing | G29: =SUMIF($M$53:$M$90, $B$29, G53:G90) -> 2.4 | H29: =SUMIF($M$53:$M$90, $B$29, H53:H90) -> 127.1 | I29: =SUMIF($M$53:$M$90, $B$29, I53:I90) -> -264 | J29: =SUMIF($M$53:$M$90, $B$29, J53:J90) -> -169 | K29: =SUMIF($M$53:$M$90, $B$29, K53:K90) -> 10 | L29: =SUMIF($M$53:$M$90, $B$29, L53:L90) -> 442 | M29: ='Debt & Cash'!K63 -> 54.671794 | N29: ='Debt & Cash'!L63 -> 49.770364 | O29: ='Debt & Cash'!M63 -> 85.255476 | P29: ='Debt & Cash'!N63 -> 104.22761 | Q29: ='Debt & Cash'!O63 -> 133.02323
B30: Net Change related to Equity | G30: =SUMIF($M$53:$M$90, $B$30, G53:G90) -> 0 | H30: =SUMIF($M$53:$M$90, $B$30, H53:H90) -> 298.4 | I30: =SUMIF($M$53:$M$90, $B$30, I53:I90) -> -3 | J30: =SUMIF($M$53:$M$90, $B$30, J53:J90) -> 0 | K30: =SUMIF($M$53:$M$90, $B$30, K53:K90) -> 238 | L30: =SUMIF($M$53:$M$90, $B$30, L53:L90) -> -1 | M30: 0 | N30: 0 | O30: 0 | P30: 0 | Q30: 0 | R30: (Share amount is kept constant)
B31: Payment of Lease Liabilities | G31: =SUMIF($M$53:$M$90, $B$31, G53:G90) -> -11.3 | H31: =SUMIF($M$53:$M$90, $B$31, H53:H90) -> -14.3 | I31: =SUMIF($M$53:$M$90, $B$31, I53:I90) -> -16 | J31: =SUMIF($M$53:$M$90, $B$31, J53:J90) -> -19 | K31: =SUMIF($M$53:$M$90, $B$31, K53:K90) -> -19 | L31: =SUMIF($M$53:$M$90, $B$31, L53:L90) -> -27 | M31: 0 | N31: 0 | O31: 0 | P31: 0 | Q31: 0 | R31: (Already Included in Change in Debt/Financing)
B32: Dividends Paid | G32: =SUMIF($M$53:$M$90, $B$32, G53:G90) -> -0.2 | H32: =SUMIF($M$53:$M$90, $B$32, H53:H90) -> 0 | I32: =SUMIF($M$53:$M$90, $B$32, I53:I90) -> -14 | J32: =SUMIF($M$53:$M$90, $B$32, J53:J90) -> -26 | K32: =SUMIF($M$53:$M$90, $B$32, K53:K90) -> -32 | L32: =SUMIF($M$53:$M$90, $B$32, L53:L90) -> -46 | M32: ='Debt & Cash'!K25*-1 -> -137.33807 | N32: ='Debt & Cash'!L25*-1 -> -155.5185 | O32: ='Debt & Cash'!M25*-1 -> -218.47683 | P32: ='Debt & Cash'!N25*-1 -> -272.46882 | Q32: ='Debt & Cash'!O25*-1 -> -342.63831
B33: Other Financing Activities | G33: =SUMIF($M$53:$M$90, $B$33, G53:G90) -> 0 | H33: =SUMIF($M$53:$M$90, $B$33, H53:H90) -> 0 | I33: =SUMIF($M$53:$M$90, $B$33, I53:I90) -> 0 | J33: =SUMIF($M$53:$M$90, $B$33, J53:J90) -> 0 | K33: =SUMIF($M$53:$M$90, $B$33, K53:K90) -> 0 | L33: =SUMIF($M$53:$M$90, $B$33, L53:L90) -> 0 | M33: 0 | N33: 0 | O33: 0 | P33: 0 | Q33: 0
B34: Net Cash from Financing Activities | G34: =SUM(G29:G33) -> -9.1 | H34: =SUM(H29:H33) -> 411.2 | I34: =SUM(I29:I33) -> -297 | J34: =SUM(J29:J33) -> -214 | K34: =SUM(K29:K33) -> 197 | L34: =SUM(L29:L33) -> 368 | M34: =SUM(M29:M33) -> -82.666277 | N34: =SUM(N29:N33) -> -105.74813 | ... Q34: =SUM(Q29:Q33) -> -209.61507
B36: FX Effect & Net Change
B37: Effect of Exchange Rates on Cash | G37: =SUMIF($M$53:$M$90, $B$37,G53:G90) -> 1.4 | H37: =SUMIF($M$53:$M$90, $B$37,H53:H90) -> -2.3 | I37: =SUMIF($M$53:$M$90, $B$37,I53:I90) -> -1 | J37: =SUMIF($M$53:$M$90, $B$37,J53:J90) -> 2 | K37: =SUMIF($M$53:$M$90, $B$37,K53:K90) -> 0 | L37: =SUMIF($M$53:$M$90, $B$37,L53:L90) -> -3 | M37: 0 | N37: 0 | O37: 0 | P37: 0 | Q37: 0 | R37: (FX is impossible to forecast, especially with the expansion in multiple jurisdictions/currencies who will have offsetting effects, therefore kept at 0)
B38: Net Change in Cash & Equivalents | G38: =SUM(G34,G26,G20,G37) -> -90.1 | H38: =SUM(H34,H26,H20,H37) -> 510.9 | I38: =SUM(I34,I26,I20,I37) -> -116 | J38: =SUM(J34,J26,J20,J37) -> -69 | K38: =SUM(K34,K26,K20,K37) -> 340 | L38: =SUM(L34,L26,L20,L37) -> -67 | M38: =M34+M26+M20 -> 203.21801 | N38: =N34+N26+N20 -> 200.35739 | O38: =O34+O26+O20 -> 349.49352 | P38: =P34+P26+P20 -> 339.21297 | Q38: =Q34+Q26+Q20 -> 398.31994
B40: Cash Balances
B42: Cash & Equivalents (Beginning)
B43: Cash & Equivalents (End)
B50: Reported Cash Flow Statement
G51: 2019 | H51: 2020 | I51: 2021 | J51: 2022 | K51: 2023 | L51: 2024
B52: Group profit / loss | G52: 8.2 | H52: -64.5 | I52: 63 | J52: 80 | K52: 58 | L52: 106
B53: Depreciation, amortisation and impairments of non-current assets | G53: 129.6 | H53: 120.8 | I53: 126 | J53: 103 | K53: 117 | L53: 162 | M53: Adjustments for Non-Cash Items
B54: Impairments (+) / reversals of impairments (-) of inventories, trade receivables and contract assets | G54: 13.2 | H54: -2.4 | I54: 3 | J54: 2 | K54: 17 | L54: 17 | M54: Adjustments for Non-Cash Items
B55: Profit / loss from disposals of non-current assets | G55: 0.4 | H55: 0 | I55: -1 | J55: 0 | K55: -1 | L55: 1 | M55: Adjustments for Non-Cash Items
B56: Share of profits in investments accounted for using the equity method | G56: 1.2 | H56: 2.6 | I56: 2 | J56: 0 | K56: 0 | L56: -3 | M56: Other Investing Activities
B57: Financial expenses (net) | G57: 24.6 | H57: 128.3 | I57: 33 | J57: 27 | K57: 41 | L57: 56 | M57: Other Investing Activities
B58: Other non-cash expense / income | G58: -5.4 | H58: -5.1 | I58: -4 | J58: 1 | K58: 14 | L58: -4 | M58: Other Investing Activities
...

Sheet Revenue & Expenses (updated)
A1: =_xlfn.CONCAT(Inputs!C7, " - ", "Assumptions"," - ", "in ", Inputs!C9, " ", Inputs!C10) -> HAG - Assumptions - in Euro millions
B4: Financial year end | G4: =EDATE(Inputs!$C$8, G5*12) -> 43830 | H4: =EDATE(Inputs!$C$8, H5*12) -> 44196 | I4: =EDATE(Inputs!$C$8, I5*12) -> 44561 | J4: =EDATE(Inputs!$C$8, J5*12) -> 44926 | K4: =EDATE(Inputs!$C$8, K5*12) -> 45291 | L4: =EDATE(Inputs!$C$8, L5*12) -> 45657 | M4: =EDATE(Inputs!$C$8, M5*12) -> 46022 | N4: =EDATE(Inputs!$C$8, N5*12) -> 46387 | ... Q4: =EDATE(Inputs!$C$8, Q5*12) -> 47483 | S4: Revenue Conversion Rate | V4: =Inputs!N7 -> 3
B5: Time-line counter | G5: -5 | H5: -4 | I5: -3 | J5: -2 | K5: -1 | L5: 0 | M5: 1 | N5: 2 | O5: 3 | P5: 4 | Q5: 5 | S5: Revenue Growth Rate | V5: =Inputs!N8 -> 3
B6: Currency and units | G6: =_xlfn.CONCAT(Inputs!$C$9, " ", Inputs!$C$10) -> Euro millions | H6: =_xlfn.CONCAT(Inputs!$C$9, " ", Inputs!$C$10) -> Euro millions | I6: =_xlfn.CONCAT(Inputs!$C$9, " ", Inputs!$C$10) -> Euro millions | J6: =_xlfn.CONCAT(Inputs!$C$9, " ", Inputs!$C$10) -> Euro millions | K6: =_xlfn.CONCAT(Inputs!$C$9, " ", Inputs!$C$10) -> Euro millions | L6: =_xlfn.CONCAT(Inputs!$C$9, " ", Inputs!$C$10) -> Euro millions | M6: =_xlfn.CONCAT(Inputs!$C$9, " ", Inputs!$C$10) -> Euro millions | N6: =_xlfn.CONCAT(Inputs!$C$9, " ", Inputs!$C$10) -> Euro millions | ... Q6: =_xlfn.CONCAT(Inputs!$C$9, " ", Inputs!$C$10) -> Euro millions | S6: Book to Bill Ratio | V6: =Inputs!N9 -> 3
B7: Time-Stamp | G7: =IF(G5<=0, "Historical", "Forecasted") -> Historical | H7: =IF(H5<=0, "Historical", "Forecasted") -> Historical | I7: =IF(I5<=0, "Historical", "Forecasted") -> Historical | J7: =IF(J5<=0, "Historical", "Forecasted") -> Historical | K7: =IF(K5<=0, "Historical", "Forecasted") -> Historical | L7: =IF(L5<=0, "Historical", "Forecasted") -> Historical | M7: =IF(M5<=0, "Historical", "Forecasted") -> Forecasted | N7: =IF(N5<=0, "Historical", "Forecasted") -> Forecasted | ... Q7: =IF(Q5<=0, "Historical", "Forecasted") -> Forecasted | S7: Cost of Sales | V7: =Inputs!N10 -> 4
S8: SG&A | V8: =Inputs!N11 -> 3
S9: R&D | V9: =Inputs!N12 -> 3
S10: Other Income | V10: =Inputs!N13 -> 3
B11: Revenue Model | Q11: =((Q22/L22)^(1/5))-1 -> 0.17841293
B14: Actual Revenue Forecast
B15: Beginnign Backlog | H15: 2202 | I15: 3424 | J15: 5092 | K15: 5366 | L15: 5530 | M15: 6644 | N15: =M21 -> 8238.6 | O15: =N21 -> 9457.0956 | P15: =O21 -> 11273.993 | Q15: =P21 -> 13259.586 | S15: Assumptions about Scenarios
B16: Backlog Conversion rate | H16: =H17/H15 -> 0.54768392 | I16: =I17/I15 -> 0.43049065 | J16: =J17/J15 -> 0.33523174 | K16: =K17/K15 -> 0.34923593 | L16: =L17/L15 -> 0.40506329 | M16: =CHOOSE($V$4, M25, M26,M27,M28) -> 0.35 | N16: =CHOOSE($V$4, N25, N26,N27,N28) -> 0.35 | O16: =CHOOSE($V$4, O25, O26,O27,O28) -> 0.35 | P16: =CHOOSE($V$4, P25, P26,P27,P28) -> 0.35 | Q16: =CHOOSE($V$4, Q25, Q26,Q27,Q28) -> 0.35
B17: Backlog Conversion Revenue | G17: 1114 | H17: =U35 -> 1206 | I17: =V35 -> 1474 | J17: =W35 -> 1707 | K17: =X35 -> 1874 | L17: =Y35 -> 2240 | M17: =M15*M16 -> 2325.4 | N17: =N15*N16 -> 2883.51 | O17: =O15*O16 -> 3309.9835 | P17: =P15*P16 -> 3945.8975 | Q17: =Q15*Q16 -> 4640.855 | S17: Revenue:
B18: Revenue Growth Rate | H18: =(H17-G17)/G17 -> 0.082585278 | I18: =(I17-H17)/H17 -> 0.22222222 | J18: =(J17-I17)/I17 -> 0.15807327 | K18: =(K17-J17)/J17 -> 0.097832455 | L18: =(L17-K17)/K17 -> 0.19530416 | M18: =CHOOSE($V$5,M31,M32,M33,M34) -> 0.25 | N18: =CHOOSE($V$5,N31,N32,N33,N34) -> 0.26 | O18: =CHOOSE($V$5,O31,O32,O33,O34) -> 0.27 | P18: =CHOOSE($V$5,P31,P32,P33,P34) -> 0.28 | Q18: =CHOOSE($V$5,Q31,Q32,Q33,Q34) -> 0.29 | S18: While the Structural drivers (uncertain global environment, continuing increases in defense spending in HAG core business areas, fiscal expansion)
B19: Book to Bill Ratio | G19: =1040/1114 -> 0.93357271 | H19: =2541/1206 -> 2.1069652 | I19: 2.2 | J19: 1.2 | K19: 1.1 | L19: 1.3 | M19: =CHOOSE($V$6,M37,M38,M39,M40) -> 1.4 | N19: =CHOOSE($V$6,N37,N38,N39,N40) -> 1.4 | O19: =CHOOSE($V$6,O37,O38,O39,O40) -> 1.4 | P19: =CHOOSE($V$6,P37,P38,P39,P40) -> 1.4 | Q19: =CHOOSE($V$6,Q37,Q38,Q39,Q40) -> 1.4 | S19: are in tact, there are significant risks - ie if the Russia-Ukrain War stops and defense spending does not follow the forecasted path to reach 3.5% in 2035 for all Nato countries (except Spain)
B20: New Order Intake | G20: 1040 | H20: 2541 | I20: 3171 | J20: 1993 | K20: 2087 | L20: 2904 | M20: =M22*M19 -> 3920 | N20: =N22*N19 -> 4102.0056 | O20: =O22*O19 -> 5126.8808 | P20: =P22*P19 -> 5931.4904 | Q20: =Q22*Q19 -> 7126.2909 | S20: Growth therefore depends not only on governments desire to purchase but also to deliver on the backlog and expand into new markets, especially in the middle east
B21: Ending Backlog | G21: =G15+G20-G17 -> -74 | H21: =H15+H20-H17 -> 3537 | I21: =I15+I20-I17 -> 5121 | J21: =J15+J20-J17 -> 5378 | K21: =K15+K20-K17 -> 5579 | L21: =L15+L20-L17 -> 6194 | M21: =M15+M20-M17 -> 8238.6 | N21: =N15+N20-N17 -> 9457.0956 | ... Q21: =Q15+Q20-Q17 -> 15745.022
B22: Total Revenue Forecast | H22: =G17*(1+H18) -> 1206 | I22: =H17*(1+I18) -> 1474 | J22: =I17*(1+J18) -> 1707 | K22: =J17*(1+K18) -> 1874 | L22: =K17*(1+L18) -> 2240 | M22: =L17*(1+M18) -> 2800 | N22: =M17*(1+N18) -> 2930.004 | O22: =N17*(1+O18) -> 3662.0577 | ... Q22: =P17*(1+Q18) -> 5090.2078 | S22: Bookt to Bill Ratio
S23: While the current book to bill ratio of 1,2 indicates significant future backlog, HAG believes, that they can accellarate their own growth by entering new markets
B24: Backlog Conversion Rate | S24: and refocussing their offering from products to a solutions based approach. This is underlined by the aquisition of a new business (ESG) in 2024
A25: 1 | B25: Pessimistic Sceanrio | M25: 0.28 | N25: 0.28 | O25: 0.28 | P25: 0.28 | Q25: 0.28
A26: 2 | B26: Realistic Scenario | M26: 0.31 | N26: 0.31 | O26: 0.31 | P26: 0.31 | Q26: 0.31 | S26: Conversion Rate
A27: 3 | B27: Optimistic Scenario | M27: 0.35 | N27: 0.35 | O27: 0.35 | P27: 0.35 | Q27: 0.35 | S27: This essentially measures, how much of the existing backlog hensoldt is able to turn into billable revenue. Since HAG is continuously increasing capactiy
A28: 4 | B28: Company own Projection | M28: 0.3 | N28: 0.3 | O28: 0.3 | P28: 0.3 | Q28: 0.3 | S28: either in personall but also on in terms of sheet product output with a record almost 130 million in R&D Spending in 2025, it is very likely, that large parts of the backlog can be turned into actionable growth.
S29: Although comparative disadvantages exist for any industrial production in Europe, the defense sector is somewhat isolated from this due to the
B30: Revenue Growth Rate | S30: increasing willingness of all participant (planning agencies, banks, regulators, potential employees) to support it's companies.
B31: Pessimistic Sceanrio | M31: 0.2 | N31: 0.19 | O31: 0.18 | P31: 0.18 | Q31: 0.18
B32: Realistic Scenario | M32: 0.22 | N32: 0.22 | O32: 0.22 | P32: 0.22 | Q32: 0.22
B33: Optimistic Scenario | M33: 0.25 | N33: 0.26 | O33: 0.27 | P33: 0.28 | Q33: 0.29 | S33: Conversion Calculation | T33: 2019 | U33: 2020 | V33: 2021 | W33: 2022 | X33: 2023 | Y33: 2024
B34: Company own Projection | M34: 0.24 | N34: 0.25 | O34: 0.26 | P34: 0.26 | Q34: 0.26 | S34: Total Order Backlog | T34: 2202 | U34: 3424 | V34: 5092 | W34: 5366 | X34: 5530 | Y34: 6644
S35: Annual Sales | T35: 1114 | U35: 1206 | V35: 1474 | W35: 1707 | X35: 1874 | Y35: 2240
B36: Book to Bill Ratio | S36: Conversion Rate | T36: =U35/T34 -> 0.54768392 | U36: =V35/U34 -> 0.43049065 | V36: =W35/V34 -> 0.33523174 | W36: =X35/W34 -> 0.34923593 | X36: =Y35/X34 -> 0.40506329 | Y36: =Z7/Y34 -> 0
B37: Pessimistic Sceanrio | M37: 1.2 | N37: 1.2 | O37: 1.2 | P37: 1.2 | Q37: 1.2 | S37: GR Order Backlog | U37: =(U34-T34)/T34 -> 0.55495005 | V37: =(V34-U34)/U34 -> 0.48714953 | W37: =(W34-V34)/V34 -> 0.053809898 | X37: =(X34-W34)/W34 -> 0.030562803 | Y37: =(Y34-X34)/X34 -> 0.20144665
B38: Realistic Scenario | M38: 1.3 | N38: 1.3 | O38: 1.3 | P38: 1.3 | Q38: 1.3 | S38: GR Revenue | U38: =(U35-T35)/T35 -> 0.082585278 | V38: =(V35-U35)/U35 -> 0.22222222 | W38: =(W35-V35)/V35 -> 0.15807327 | X38: =(X35-W35)/W35 -> 0.097832455 | Y38: =(Y35-X35)/X35 -> 0.19530416
B39: Optimistic Scenario | M39: 1.4 | N39: 1.4 | O39: 1.4 | P39: 1.4 | Q39: 1.4
B40: Company own Projection | M40: 1.3 | N40: 1.35 | O40: 1.4 | P40: 1.5 | Q40: 1.5
S41: Margin Calculations | T41: 2019 | U41: 2020 | V41: 2021 | W41: 2022 | X41: 2023 | Y41: 2024
B42: Expense Model | S42: Revenue | T42: =IS!D10 -> 1114.2 | U42: =IS!E10 -> 1206.9 | V42: =IS!F10 -> 1474 | W42: =IS!G10 -> 1707 | X42: =IS!H10 -> 1847 | Y42: =IS!I10 -> 2240 | Z42: =M22 -> 2800 | AA42: =N22 -> 2930.004 | AB42: =O22 -> 3662.0577 | AC42: =P22 -> 4236.7788 | AD42: =Q22 -> 5090.2078
S43: Cost of Sales | T43: =IS!D11 -> -859.3 | U43: =IS!E11 -> -936.1 | V43: =IS!F11 -> -1144 | W43: =IS!G11 -> -1314 | X43: =IS!H11 -> -1427 | Y43: =IS!I11 -> -1732 | Z43: =M45*-1 -> -1960 | AA43: =N45*-1 -> -2021.7028 | AB43: =O45*-1 -> -2490.1992 | AC43: =P45*-1 -> -2881.0096 | AD43: =Q45*-1 -> -3461.3413
B44: Actual Expense Forecast | S44: Operating Margin | T44: =1-((-1)*T43/T42) -> 0.22877401 | U44: =1-((-1)*U43/U42) -> 0.2243765 | V44: =1-((-1)*V43/V42) -> 0.2238806 | W44: =1-((-1)*W43/W42) -> 0.23022847 | X44: =1-((-1)*X43/X42) -> 0.22739578 | Y44: =1-((-1)*Y43/Y42) -> 0.22678571 | Z44: =1-((-1)*Z43/Z42) -> 0.3 | AA44: =1-((-1)*AA43/AA42) -> 0.31 | ... AD44: =1-((-1)*AD43/AD42) -> 0.32
...

Sheet FA-Forecast (updated)
A1: =_xlfn.CONCAT(Inputs!C7, " - ", "Fixed Assets", " - ", "in ", Inputs!C9, " ", Inputs!C10) -> HAG - Fixed Assets - in Euro millions
V2: Version
B4: Financial year end | G4: =EDATE(Inputs!$C$8, G5*12) -> 43830 | H4: =EDATE(Inputs!$C$8, H5*12) -> 44196 | I4: =EDATE(Inputs!$C$8, I5*12) -> 44561 | J4: =EDATE(Inputs!$C$8, J5*12) -> 44926 | K4: =EDATE(Inputs!$C$8, K5*12) -> 45291 | L4: =EDATE(Inputs!$C$8, L5*12) -> 45657 | M4: =EDATE(Inputs!$C$8, M5*12) -> 46022 | N4: =EDATE(Inputs!$C$8, N5*12) -> 46387 | ... Q4: =EDATE(Inputs!$C$8, Q5*12) -> 47483 | S4: Capex | V4: =Inputs!R7 -> 3
B5: Time-line counter | G5: -5 | H5: -4 | I5: -3 | J5: -2 | K5: -1 | L5: 0 | M5: 1 | N5: 2 | O5: 3 | P5: 4 | Q5: 5 | S5: D&A | V5: =Inputs!R8 -> 3
B6: Currency and units | G6: =_xlfn.CONCAT(Inputs!$C$9, " ", Inputs!$C$10) -> Euro millions | H6: =_xlfn.CONCAT(Inputs!$C$9, " ", Inputs!$C$10) -> Euro millions | I6: =_xlfn.CONCAT(Inputs!$C$9, " ", Inputs!$C$10) -> Euro millions | J6: =_xlfn.CONCAT(Inputs!$C$9, " ", Inputs!$C$10) -> Euro millions | K6: =_xlfn.CONCAT(Inputs!$C$9, " ", Inputs!$C$10) -> Euro millions | L6: =_xlfn.CONCAT(Inputs!$C$9, " ", Inputs!$C$10) -> Euro millions | M6: =_xlfn.CONCAT(Inputs!$C$9, " ", Inputs!$C$10) -> Euro millions | N6: =_xlfn.CONCAT(Inputs!$C$9, " ", Inputs!$C$10) -> Euro millions | ... Q6: =_xlfn.CONCAT(Inputs!$C$9, " ", Inputs!$C$10) -> Euro millions | S6: Disposals | V6: =Inputs!R9 -> 3
B7: Time-Stamp | G7: =IF(G5<=0, "Historical", "Forecasted") -> Historical | H7: =IF(H5<=0, "Historical", "Forecasted") -> Historical | I7: =IF(I5<=0, "Historical", "Forecasted") -> Historical | J7: =IF(J5<=0, "Historical", "Forecasted") -> Historical | K7: =IF(K5<=0, "Historical", "Forecasted") -> Historical | L7: =IF(L5<=0, "Historical", "Forecasted") -> Historical | M7: =IF(M5<=0, "Historical", "Forecasted") -> Forecasted | N7: =IF(N5<=0, "Historical", "Forecasted") -> Forecasted | ... Q7: =IF(Q5<=0, "Historical", "Forecasted") -> Forecasted
B9: Targeted Scenario | E9: 1 | K9: Forecasted Revenue | M9: ='Revenue & Expenses (updated)'!M22 -> 2800 | N9: ='Revenue & Expenses (updated)'!N22 -> 2930.004 | O9: ='Revenue & Expenses (updated)'!O22 -> 3662.0577 | P9: ='Revenue & Expenses (updated)'!P22 -> 4236.7788 | Q9: ='Revenue & Expenses (updated)'!Q22 -> 5090.2078
S10: Basic Principle:
B11: PPE | S11: Operating Items are based on Revenue
B12: Beginning Gross PPE | G12: 126 | H12: 151 | I12: 180 | J12: 208 | K12: 282 | L12: 370 | M12: =L17 -> 448.35 | N12: =M17 -> 539.62475 | O12: =N17 -> 634.08052 | P12: =O17 -> 752.74133 | Q12: =P17 -> 889.73747 | S12: Financing&Investing on a roll forward scheduel (add to previous years amount and subtract from it)
B13: (+) CapEX | E13: =T20 -> 0.27 | G13: 21 | H13: 31 | I13: 30 | J13: 36 | K13: 46 | L13: 83 | M13: =M14*M9 -> 98 | N13: =N14*N9 -> 102.55014 | O13: =O14*O9 -> 128.17202 | P13: =P14*P9 -> 148.28726 | Q13: =Q14*Q9 -> 178.15727 | S13: Other items are idiosyncratic/forecasted by using company guidance
B14: % used | G14: =G13/G12 -> 0.16666667 | H14: =H13/H12 -> 0.20529801 | I14: =I13/I12 -> 0.16666667 | J14: =J13/J12 -> 0.17307692 | K14: =K13/K12 -> 0.16312057 | L14: 0.35 | M14: =CHOOSE($E$9,M60,M61,M62,M63)*$L$14 -> 0.035 | N14: =CHOOSE($E$9,N60,N61,N62,N63)*$L$14 -> 0.035 | O14: =CHOOSE($E$9,O60,O61,O62,O63)*$L$14 -> 0.035 | P14: =CHOOSE($E$9,P60,P61,P62,P63)*$L$14 -> 0.035 | Q14: =CHOOSE($E$9,Q60,Q61,Q62,Q63)*$L$14 -> 0.035
B15: (-) Disposals | G15: -1 | H15: -3 | I15: -4 | J15: -2 | K15: -3 | L15: -5 | M15: =(-1)*M16*M12 -> -6.72525 | N15: =(-1)*N16*N12 -> -8.0943713 | O15: =(-1)*O16*O12 -> -9.5112078 | P15: =(-1)*P16*P12 -> -11.29112 | Q15: =(-1)*Q16*Q12 -> -13.346062
B16: % used | M16: =CHOOSE($E$9,M78,M79,M80,M81) -> 0.015 | N16: =CHOOSE($E$9,N78,N79,N80,N81) -> 0.015 | O16: =CHOOSE($E$9,O78,O79,O80,O81) -> 0.015 | P16: =CHOOSE($E$9,P78,P79,P80,P81) -> 0.015 | Q16: =CHOOSE($E$9,Q78,Q79,Q80,Q81) -> 0.015
B17: Ending Gross PPE | G17: =SUM(G12:G15) -> 146.16667 | H17: =SUM(H12:H15) -> 179.2053 | I17: =SUM(I12:I15) -> 206.16667 | J17: =SUM(J12:J15) -> 242.17308 | K17: =SUM(K12:K15) -> 325.16312 | L17: =SUM(L12:L15) -> 448.35 | M17: =SUM(M12,M13,M15) -> 539.62475 | N17: =SUM(N12,N13,N15) -> 634.08052 | O17: =SUM(O12,O13,O15) -> 752.74133 | P17: =SUM(P12,P13,P15) -> 889.73747 | Q17: =SUM(Q12,Q13,Q15) -> 1054.5487
B19: Depreciation (PPE) | S19: Capex Distribution | V19: D&A Distribution
B20: Beginning Accumulating Depreciation | G20: -37 | H20: -58 | I20: -77 | J20: -100 | K20: -120 | L20: -142 | M20: =L24 -> -167 | N20: =M24 -> -219.22789 | O20: =N24 -> -273.27345 | P20: =O24 -> -330.9337 | Q20: =P24 -> -393.36683 | S20: PPE | T20: 0.27 | V20: PPE | W20: 0.21
B21: (+) D&A Expense for PPE | E21: =W20 -> 0.21 | G21: -21 | H21: -22 | I21: -23 | J21: -22 | K21: -25 | L21: -28 | M21: =CHOOSE($V$5,M69,M70,M71,M72)*M68*$E$21*-1 -> -55.227894 | N21: =CHOOSE($V$5,N69,N70,N71,N72)*N68*$E$21*-1 -> -57.045554 | O21: =CHOOSE($V$5,O69,O70,O71,O72)*O68*$E$21*-1 -> -60.660252 | P21: =CHOOSE($V$5,P69,P70,P71,P72)*P68*$E$21*-1 -> -65.433131 | Q21: =CHOOSE($V$5,Q69,Q70,Q71,Q72)*Q68*$E$21*-1 -> -72.00371 | S21: Intangibles | T21: 0.4 | V21: Intangibles | W21: 0.58
B22: % used | M22: =CHOOSE($E$9,M69,M70,M71,M72)*$E$21 -> 0.0315 | N22: =CHOOSE($E$9,N69,N70,N71,N72)*$E$21 -> 0.0315 | O22: =CHOOSE($E$9,O69,O70,O71,O72)*$E$21 -> 0.0315 | P22: =CHOOSE($E$9,P69,P70,P71,P72)*$E$21 -> 0.0315 | Q22: =CHOOSE($E$9,Q69,Q70,Q71,Q72)*$E$21 -> 0.0315 | S22: ROU | T22: 0.33 | V22: ROU | W22: 0.22
B23: (-) Accum Dep. On Disposals | G23: 1 | H23: 2 | I23: 2 | J23: 2 | K23: 2 | L23: 3 | M23: =L23 -> 3 | N23: =M23 -> 3 | O23: =N23 -> 3 | P23: =O23 -> 3 | Q23: =P23 -> 3
B24: Ending Acc. Depreciation | G24: =SUM(G20:G23) -> -57 | H24: =SUM(H20:H23) -> -78 | I24: =SUM(I20:I23) -> -98 | J24: =SUM(J20:J23) -> -120 | K24: =SUM(K20:K23) -> -143 | L24: =SUM(L20:L23) -> -167 | M24: =SUM(M20,M21,M23) -> -219.22789 | N24: =SUM(N20,N21,N23) -> -273.27345 | O24: =SUM(O20,O21,O23) -> -330.9337 | P24: =SUM(P20,P21,P23) -> -393.36683 | Q24: =SUM(Q20,Q21,Q23) -> -462.37054
B25: Net PPE | G25: =SUM(G17,G24) -> 89.166667 | H25: =SUM(H17,H24) -> 101.2053 | I25: =SUM(I17,I24) -> 108.16667 | J25: =SUM(J17,J24) -> 122.17308 | K25: =SUM(K17,K24) -> 182.16312 | L25: =SUM(L17,L24) -> 281.35 | M25: =SUM(M17,M24) -> 320.39686 | N25: =SUM(N17,N24) -> 360.80707 | ... Q25: =SUM(Q17,Q24) -> 592.17814
G26: =-G21/G25 -> 0.23551402 | H26: =-H21/H25 -> 0.21737992 | I26: =-I21/I25 -> 0.21263482 | J26: =-J21/J25 -> 0.18007241 | K26: =-K21/K25 -> 0.13723963 | L26: =-L21/L25 -> 0.099520171
B27: Intangible Assets | S27: Core Assumptions:
B28: Beginning Net intangibles | G28: 403 | H28: 386 | I28: 385 | J28: 385 | K28: 399 | L28: 667 | M28: =L34 -> 673.17091 | N28: =M34 -> 651.64928 | O28: =N34 -> 631.75529 | P28: =O34 -> 641.97967 | Q28: =P34 -> 669.80721 | S28: Disposal is fully depreciated, so held constant
B29: (+) Capex (capitalised R&D) | E29: =T21 -> 0.4 | G29: 59 | H29: 66 | I29: 66 | J29: 60 | K29: 69 | L29: 114 | M29: =$E$29*M65 -> 134.4 | N29: =$E$29*N65 -> 140.64019 | O29: =$E$29*O65 -> 175.77877 | P29: =$E$29*P65 -> 203.36538 | Q29: =$E$29*Q65 -> 244.32997 | S29: Righ of Use Assets + 50 Miscallenious assets comprise the Other non-current assets category
B30: % used | G30: =G29/G28 -> 0.14640199 | H30: =H29/H28 -> 0.17098446 | I30: =I29/I28 -> 0.17142857 | J30: =J29/J28 -> 0.15584416 | K30: =K29/K28 -> 0.17293233 | L30: =L29/L28 -> 0.17091454 | M30: =CHOOSE($E$9,M60,M61,M62,M63)*$E$29 -> 0.04 | N30: =CHOOSE($E$9,N60,N61,N62,N63)*$E$29 -> 0.04 | O30: =CHOOSE($E$9,O60,O61,O62,O63)*$E$29 -> 0.04 | P30: =CHOOSE($E$9,P60,P61,P62,P63)*$E$29 -> 0.04 | Q30: =CHOOSE($E$9,Q60,Q61,Q62,Q63)*$E$29 -> 0.04
